<?xml version="1.0" ?>
<!-- =================================================================================== -->
<!-- |    This document was autogenerated by xacro from lwa.urdf.xacro                 | -->
<!-- |    EDITING THIS FILE BY HAND IS NOT RECOMMENDED                                 | -->
<!-- =================================================================================== -->
<robot name="schunk_lwa" xmlns:xacro="http://www.ros.org/wiki/xacro">
  <!-- see https://secure.wikimedia.org/wikipedia/en/wiki/List_of_moment_of_inertia_tensors -->
  <link name="world"/>
  <!-- joint between parent link and arm_base_link -->
  <joint name="schunk_lwa_base_joint" type="fixed">
    <parent link="world"/>
    <child link="schunk_lwa_base_link"/>
  </joint>
  <link name="schunk_lwa_base_link">
    <inertial>
      <mass value="0.01"/>
      <origin xyz="0 0 0"/>
      <inertia ixx="0.001" ixy="0.0" ixz="0.0" iyy="0.001" iyz="0.0" izz="0.001"/>
    </inertial>
    <visual>
      <origin rpy="0 0 0" xyz="0 0 0.04"/>
      <geometry>
        <cylinder length="0.08" radius="0.045"/>
      </geometry>
      <material name="orange"/>
    </visual>
    <collision>
      <origin rpy="0 0 0" xyz="0 0 0.04"/>
      <geometry>
        <cylinder length="0.08" radius="0.045"/>
      </geometry>
    </collision>
  </link>
  <!-- joint between arm_base_link and arm_1_link -->
  <joint name="schunk_lwa_1_joint" type="revolute">
    <origin rpy="0 0 3.1415926" xyz="0 0 4.0"/>
    <parent link="schunk_lwa_base_link"/>
    <child link="schunk_lwa_1_link"/>
    <axis xyz="0 0 1"/>
    <dynamics damping="10"/>
    <limit effort="370" lower="-3.1415" upper="3.1415" velocity="2.0"/>
    <!--limit effort="370" velocity="2.0" lower="-6.25" upper="6.25"/-->
    <!--safety_controller k_position="20" k_velocity="50" soft_lower_limit="${-6.25 + 0.01}" soft_upper_limit="${6.25 - 0.01}" /-->
  </joint>
  <link name="schunk_lwa_1_link">
    <inertial>
      <mass value="0.01"/>
      <origin xyz="0 0 0"/>
      <inertia ixx="0.001" ixy="0.0" ixz="0.0" iyy="0.001" iyz="0.0" izz="0.001"/>
    </inertial>
    <visual>
      <origin rpy="0 0 0" xyz="0 0 0"/>
      <geometry>
        <mesh filename="package://schunk_description/meshes/lwa/lwa1.stl"/>
      </geometry>
      <material name="black"/>
    </visual>
    <collision>
      <origin rpy="0 0 0" xyz="0 0 0"/>
      <geometry>
        <mesh filename="package://schunk_description/meshes/lwa/lwa1.stl"/>
      </geometry>
    </collision>
  </link>
  <!-- joint between arm_1_link and arm_2_link -->
  <joint name="schunk_lwa_2_joint" type="revolute">
    <origin rpy="1.5708 0 0" xyz="0 0 -0.2"/>
    <parent link="schunk_lwa_1_link"/>
    <child link="schunk_lwa_2_link"/>
    <axis xyz="0 0 1"/>
    <dynamics damping="10"/>
    <limit effort="370" lower="-1.97" upper="1.97" velocity="2.0"/>
    <!--safety_controller k_position="20" k_velocity="50" soft_lower_limit="${-1.97 + 0.01}"   soft_upper_limit="${1.97 - 0.01}" /-->
  </joint>
  <link name="schunk_lwa_2_link">
    <inertial>
      <mass value="0.01"/>
      <origin xyz="0 0 0"/>
      <inertia ixx="0.001" ixy="0.0" ixz="0.0" iyy="0.001" iyz="0.0" izz="0.001"/>
    </inertial>
    <visual>
      <origin rpy="0 0 0" xyz="0 0 0"/>
      <geometry>
        <mesh filename="package://schunk_description/meshes/lwa/lwa2.stl"/>
      </geometry>
      <material name="orange"/>
    </visual>
    <collision>
      <origin rpy="0 0 0" xyz="0 0 0"/>
      <geometry>
        <mesh filename="package://schunk_description/meshes/lwa/lwa2.stl"/>
      </geometry>
    </collision>
  </link>
  <!-- joint between arm_2_link and arm_3_link -->
  <joint name="schunk_lwa_3_joint" type="revolute">
    <origin rpy="-1.5708 0 0" xyz="0 -0.408 -0.2"/>
    <parent link="schunk_lwa_2_link"/>
    <child link="schunk_lwa_3_link"/>
    <axis xyz="0 0 1"/>
    <dynamics damping="5"/>
    <limit effort="176" lower="-3.1415" upper="3.1415" velocity="2.0"/>
    <!--limit effort="176" velocity="2.0" lower="-6.25" upper="6.25"/-->
    <!--safety_controller k_position="20" k_velocity="25" soft_lower_limit="${-6.25 + 0.01}" soft_upper_limit="${6.25 - 0.01}" /-->
  </joint>
  <link name="schunk_lwa_3_link">
    <inertial>
      <mass value="0.01"/>
      <origin xyz="0 0 0"/>
      <inertia ixx="0.001" ixy="0.0" ixz="0.0" iyy="0.001" iyz="0.0" izz="0.001"/>
    </inertial>
    <visual>
      <origin rpy="0 0 0" xyz="0 0 0"/>
      <geometry>
        <mesh filename="package://schunk_description/meshes/lwa/lwa3.stl"/>
      </geometry>
      <material name="black"/>
    </visual>
    <collision>
      <origin rpy="0 0 0" xyz="0 0 0"/>
      <geometry>
        <mesh filename="package://schunk_description/meshes/lwa/lwa3.stl"/>
      </geometry>
    </collision>
  </link>
  <!-- joint between arm_3_link and arm_4_link -->
  <joint name="schunk_lwa_4_joint" type="revolute">
    <origin rpy="1.5708 0 0" xyz="0 0 -0.2"/>
    <parent link="schunk_lwa_3_link"/>
    <child link="schunk_lwa_4_link"/>
    <axis xyz="0 0 1"/>
    <dynamics damping="5"/>
    <limit effort="176" lower="-1.97" upper="1.97" velocity="2.0"/>
    <!--safety_controller k_position="20" k_velocity="25" soft_lower_limit="${-1.97 + 0.01}" soft_upper_limit="${1.97 - 0.01}" /-->
  </joint>
  <link name="schunk_lwa_4_link">
    <inertial>
      <mass value="0.01"/>
      <origin xyz="0 0 0"/>
      <inertia ixx="0.001" ixy="0.0" ixz="0.0" iyy="0.001" iyz="0.0" izz="0.001"/>
    </inertial>
    <visual>
      <origin rpy="0 0 0" xyz="0 0 0"/>
      <geometry>
        <mesh filename="package://schunk_description/meshes/lwa/lwa4.stl"/>
      </geometry>
      <material name="orange"/>
    </visual>
    <collision>
      <origin rpy="0 0 0" xyz="0 0 0"/>
      <geometry>
        <mesh filename="package://schunk_description/meshes/lwa/lwa4.stl"/>
      </geometry>
    </collision>
  </link>
  <!-- joint between arm_4_link and arm_5_link -->
  <joint name="schunk_lwa_5_joint" type="revolute">
    <origin rpy="-1.5708 0 0" xyz="0 -0.3165 -0.2"/>
    <parent link="schunk_lwa_4_link"/>
    <child link="schunk_lwa_5_link"/>
    <axis xyz="0 0 1"/>
    <dynamics damping="5"/>
    <limit effort="41.6" lower="-3.1415" upper="3.1415" velocity="2.0"/>
    <!--limit effort="41.6" velocity="2.0" lower="-6.25" upper="6.25" /-->
    <!--safety_controller k_position="20" k_velocity="25" soft_lower_limit="${-6.25 + 0.01}" soft_upper_limit="${6.25 - 0.01}" /-->
  </joint>
  <link name="schunk_lwa_5_link">
    <inertial>
      <mass value="0.01"/>
      <origin xyz="0 0 0"/>
      <inertia ixx="0.001" ixy="0.0" ixz="0.0" iyy="0.001" iyz="0.0" izz="0.001"/>
    </inertial>
    <visual>
      <origin rpy="0 0 0" xyz="0 0 0"/>
      <geometry>
        <mesh filename="package://schunk_description/meshes/lwa/lwa5.stl"/>
      </geometry>
      <material name="black"/>
    </visual>
    <collision>
      <origin rpy="0 0 0" xyz="0 0 0"/>
      <geometry>
        <mesh filename="package://schunk_description/meshes/lwa/lwa5.stl"/>
      </geometry>
    </collision>
  </link>
  <!-- joint between arm_5_link and arm_6_link -->
  <joint name="schunk_lwa_6_joint" type="revolute">
    <origin rpy="1.5708 0 0" xyz="0 0 -0.2"/>
    <parent link="schunk_lwa_5_link"/>
    <child link="schunk_lwa_6_link"/>
    <axis xyz="0 0 1"/>
    <dynamics damping="5"/>
    <limit effort="20.1" lower="-1.97" upper="1.97" velocity="2.0"/>
    <!--safety_controller k_position="20" k_velocity="25" soft_lower_limit="${-1.97 + 0.01}" soft_upper_limit="${1.97 - 0.01}" /-->
  </joint>
  <link name="schunk_lwa_6_link">
    <inertial>
      <mass value="0.01"/>
      <origin xyz="0 0 0"/>
      <inertia ixx="0.001" ixy="0.0" ixz="0.0" iyy="0.001" iyz="0.0" izz="0.001"/>
    </inertial>
    <visual>
      <origin rpy="0 0 0" xyz="0 0 0"/>
      <geometry>
        <mesh filename="package://schunk_description/meshes/lwa/lwa6.stl"/>
      </geometry>
      <material name="orange"/>
    </visual>
    <collision>
      <origin rpy="0 0 0" xyz="0 0 0"/>
      <geometry>
        <mesh filename="package://schunk_description/meshes/lwa/lwa6.stl"/>
      </geometry>
    </collision>
  </link>
  <!-- joint between arm_6_link and arm_7_link -->
  <joint name="schunk_lwa_7_joint" type="revolute">
    <origin rpy="-1.5708 0 0" xyz="0 -0.1927 -0.2"/>
    <parent link="schunk_lwa_6_link"/>
    <child link="schunk_lwa_7_link"/>
    <axis xyz="0 0 1"/>
    <dynamics damping="5"/>
    <limit effort="9.6" lower="-3.1415" upper="3.1415" velocity="2.0"/>
    <!--limit effort="9.6" velocity="2.0" lower="-6.25" upper="6.25" /-->
    <!--safety_controller k_position="20" k_velocity="25" soft_lower_limit="${-6.25 + 0.01}" soft_upper_limit="${6.25 - 0.01}" /-->
  </joint>
  <link name="schunk_lwa_7_link">
    <inertial>
      <mass value="0.01"/>
      <origin xyz="0 0 0"/>
      <inertia ixx="0.001" ixy="0.0" ixz="0.0" iyy="0.001" iyz="0.0" izz="0.001"/>
    </inertial>
    <visual>
      <origin rpy="0 0 0" xyz="0 0 0"/>
      <geometry>
        <mesh filename="package://schunk_description/meshes/lwa/lwa7.stl"/>
      </geometry>
      <material name="black"/>
    </visual>
    <collision>
      <origin rpy="0 0 0" xyz="0 0 0"/>
      <geometry>
        <mesh filename="package://schunk_description/meshes/lwa/lwa7.stl"/>
      </geometry>
    </collision>
  </link>
  <!-- extensions -->
  <gazebo reference="schunk_lwa_0_link">
    <gravity>true</gravity>
    <self_collide>false</self_collide>
    <material>Gazebo/Orange</material>
  </gazebo>
  <gazebo reference="schunk_lwa_1_link">
    <gravity>true</gravity>
    <self_collide>false</self_collide>
    <material>Gazebo/Black</material>
  </gazebo>
  <gazebo reference="schunk_lwa_2_link">
    <gravity>true</gravity>
    <self_collide>false</self_collide>
    <material>Gazebo/Orange</material>
  </gazebo>
  <gazebo reference="schunk_lwa_3_link">
    <gravity>true</gravity>
    <self_collide>false</self_collide>
    <material>Gazebo/Black</material>
  </gazebo>
  <gazebo reference="schunk_lwa_4_link">
    <gravity>true</gravity>
    <self_collide>false</self_collide>
    <material>Gazebo/Orange</material>
  </gazebo>
  <gazebo reference="schunk_lwa_5_link">
    <gravity>true</gravity>
    <self_collide>false</self_collide>
    <material>Gazebo/Black</material>
  </gazebo>
  <gazebo reference="schunk_lwa_6_link">
    <gravity>true</gravity>
    <self_collide>false</self_collide>
    <material>Gazebo/Orange</material>
  </gazebo>
  <gazebo reference="schunk_lwa_7_link">
    <gravity>true</gravity>
    <self_collide>false</self_collide>
    <material>Gazebo/Black</material>
  </gazebo>
  <transmission name="schunk_lwa_1_trans">
    <type>transmission_interface/SimpleTransmission</type>
    <joint name="schunk_lwa_1_joint">
      <hardwareInterface>PositionJointInterface</hardwareInterface>
    </joint>
    <actuator name="schunk_lwa_1_motor">
      <mechanicalReduction>1</mechanicalReduction>
    </actuator>
  </transmission>
  <transmission name="schunk_lwa_2_trans">
    <type>transmission_interface/SimpleTransmission</type>
    <joint name="schunk_lwa_2_joint">
      <hardwareInterface>PositionJointInterface</hardwareInterface>
    </joint>
    <actuator name="schunk_lwa_2_motor">
      <mechanicalReduction>1</mechanicalReduction>
    </actuator>
  </transmission>
  <transmission name="schunk_lwa_3_trans">
    <type>transmission_interface/SimpleTransmission</type>
    <joint name="schunk_lwa_3_joint">
      <hardwareInterface>PositionJointInterface</hardwareInterface>
    </joint>
    <actuator name="schunk_lwa_3_motor">
      <mechanicalReduction>1</mechanicalReduction>
    </actuator>
  </transmission>
  <transmission name="schunk_lwa_4_trans">
    <type>transmission_interface/SimpleTransmission</type>
    <joint name="schunk_lwa_4_joint">
      <hardwareInterface>PositionJointInterface</hardwareInterface>
    </joint>
    <actuator name="schunk_lwa_4_motor">
      <mechanicalReduction>1</mechanicalReduction>
    </actuator>
  </transmission>
  <transmission name="schunk_lwa_5_trans">
    <type>transmission_interface/SimpleTransmission</type>
    <joint name="schunk_lwa_5_joint">
      <hardwareInterface>PositionJointInterface</hardwareInterface>
    </joint>
    <actuator name="schunk_lwa_5_motor">
      <mechanicalReduction>1</mechanicalReduction>
    </actuator>
  </transmission>
  <transmission name="schunk_lwa_6_trans">
    <type>transmission_interface/SimpleTransmission</type>
    <joint name="schunk_lwa_6_joint">
      <hardwareInterface>PositionJointInterface</hardwareInterface>
    </joint>
    <actuator name="schunk_lwa_6_motor">
      <mechanicalReduction>1</mechanicalReduction>
    </actuator>
  </transmission>
  <transmission name="schunk_lwa_7_trans">
    <type>transmission_interface/SimpleTransmission</type>
    <joint name="schunk_lwa_7_joint">
      <hardwareInterface>PositionJointInterface</hardwareInterface>
    </joint>
    <actuator name="schunk_lwa_7_motor">
      <mechanicalReduction>1</mechanicalReduction>
    </actuator>
  </transmission>
</robot>
